Workbook

Sheet Result Summary (Translog) (2)
F2: FMQ | H2: Gini Coeffcient
F3: Tax Rate ($/mi) | G3: Total Revenue | H3: Urban | I3: Rural | J3: Total
E4: Without Q | F4: ='Translog Model (NEW)'!D1 -> 0.01954489 | G4: =ROUNDUP('Translog Model (NEW)'!H1,-3) -> 1624000 | H4: ='Translog Model (NEW)'!P1 -> 0.72433365 | I4: ='Translog Model (NEW)'!P2 -> 0.72589612 | J4: ='Translog Model (NEW)'!P3 -> 0.72465213
E5: With Q | F5: ='Translog Model (NEW)'!D2 -> 0.0235 | G5: =ROUNDUP('Translog Model (NEW)'!H2,-3) -> 1646000 | H5: ='Translog Model (NEW)'!N1 -> 0.71862867 | I5: ='Translog Model (NEW)'!N2 -> 0.72217445 | J5: ='Translog Model (NEW)'!N3 -> 0.71907051
E6: %∆ | F6: =(F5-F4)/F4 -> 0.20236031 | G6: =(G5-G4)/G4 -> 0.013546798 | H6: =(H5-H4)/H4 -> -0.0078761742 | I6: =(I5-I4)/I4 -> -0.005126999 | J6: =(J5-J4)/J4 -> -0.0077024777
C8: Income Group Category | D8: Households (#) | E8: Adjusted Annual VMT (mi/HH/yr) | F8: Gamma γ | G8: FMQ Qh (mi/HH/yr) | I8: Total Chargeable VMT (mi) | J8: Adjusted Revenue R ($) | K8: Current Revenue R ($) | L8: Change in Revenue ∆ ($) | M8: Fuel Tax Burden Tk ($/HH/yr) | N8: Adjusted Gini Index | O8: Current Gini Index
G9: Qbase (mi) | H9: ∆g (mi)
B10: Urban | C10: High | D10: ='Translog Model (NEW)'!B7 -> 3001 | E10: ='Translog Model (NEW)'!F7 -> 8230.5912 | F10: ='Translog Model (NEW)'!K7 -> 0 | G10: ='Translog Model (NEW)'!J7 -> 0 | H10: ='X-Old Income Group'!Q7 -> 0 | I10: ='Translog Model (NEW)'!L7 -> 24700004 | J10: ='Translog Model (NEW)'!M7 -> 580450.1 | K10: ='Translog Model (NEW)'!N7 -> 489644.56 | L10: ='Translog Model (NEW)'!O7 -> 90805.538 | M10: ='Translog Model (NEW)'!V7 -> 164.61182 | N10: ='Translog Model (NEW)'!AC7 -> 0.71862867 | O10: ='Translog Model (NEW)'!AM7 -> 0.72433365
C11: Middle High | D11: ='Translog Model (NEW)'!B8 -> 5053 | E11: ='Translog Model (NEW)'!F8 -> 5421.5541 | F11: ='Translog Model (NEW)'!K8 -> 0.1 | G11: ='Translog Model (NEW)'!J8 -> 542.15541 | I11: ='Translog Model (NEW)'!L8 -> 24655602 | J11: ='Translog Model (NEW)'!M8 -> 579406.64 | K11: ='Translog Model (NEW)'!N8 -> 541862.32 | L11: ='Translog Model (NEW)'!O8 -> 37544.317 | M11: ='Translog Model (NEW)'!V8 -> 95.69043
C12: Middle Low | D12: ='Translog Model (NEW)'!B9 -> 3458 | E12: ='Translog Model (NEW)'!F9 -> 3807.8249 | F12: ='Translog Model (NEW)'!K9 -> 0.25 | G12: ='Translog Model (NEW)'!J9 -> 951.95624 | I12: ='Translog Model (NEW)'!L9 -> 9875594 | J12: ='Translog Model (NEW)'!M9 -> 232076.46 | K12: ='Translog Model (NEW)'!N9 -> 259811.17 | L12: ='Translog Model (NEW)'!O9 -> -27734.715 | M12: ='Translog Model (NEW)'!V9 -> 53.785527
C13: Low | D13: ='Translog Model (NEW)'!B10 -> 2090 | E13: ='Translog Model (NEW)'!F10 -> 3868.5466 | F13: ='Translog Model (NEW)'!K10 -> 0.5 | G13: ='Translog Model (NEW)'!J10 -> 1934.2733 | I13: ='Translog Model (NEW)'!L10 -> 4042631.2 | J13: ='Translog Model (NEW)'!M10 -> 95001.833 | K13: ='Translog Model (NEW)'!N10 -> 159035.11 | L13: ='Translog Model (NEW)'!O10 -> -64033.275 | M13: ='Translog Model (NEW)'!V10 -> 31.915509
C14: Total | D14: ='X-Old Income Group'!B13 -> 13602 | E14: ='X-Old Income Group'!F13 -> 21376.821 | G14: ='X-Old Income Group'!J13 -> 2305.4579 | I14: ='X-Old Income Group'!L13 -> 65914101 | J14: ='X-Old Income Group'!M13 -> 1483067.3 | K14: ='X-Old Income Group'!N13 -> 1436565 | L14: ='X-Old Income Group'!O13 -> 46502.288
B15: Rural | C15: High | D15: ='Translog Model (NEW)'!B17 -> 286 | E15: ='Translog Model (NEW)'!F17 -> 9281.62 | F15: ='Translog Model (NEW)'!K17 -> 0 | G15: ='Translog Model (NEW)'!J17 -> 0 | H15: ='X-Old Income Group'!Q17 -> 1000 | I15: ='Translog Model (NEW)'!L17 -> 2368543.3 | J15: ='Translog Model (NEW)'!M17 -> 55660.768 | K15: ='Translog Model (NEW)'!N17 -> 52157.24 | L15: ='Translog Model (NEW)'!O17 -> 3503.5281 | M15: ='Translog Model (NEW)'!V17 -> 162.1324 | N15: ='Translog Model (NEW)'!N2 -> 0.72217445 | O15: ='Translog Model (NEW)'!P2 -> 0.72589612
C16: Middle High | D16: ='Translog Model (NEW)'!B18 -> 551 | E16: ='Translog Model (NEW)'!F18 -> 6802.3383 | F16: ='Translog Model (NEW)'!K18 -> 0.1 | G16: ='Translog Model (NEW)'!J18 -> 680.23383 | I16: ='X-Old Income Group'!L18 -> 2833454.8 | J16: ='X-Old Income Group'!M18 -> 63752.734 | K16: ='X-Old Income Group'!N18 -> 73513.283 | L16: ='X-Old Income Group'!O18 -> -9760.5486 | M16: ='X-Old Income Group'!V18 -> 135.81484
C17: Middle Low | D17: ='Translog Model (NEW)'!B19 -> 409 | E17: ='Translog Model (NEW)'!F19 -> 5642.2646 | F17: ='Translog Model (NEW)'!K19 -> 0.25 | G17: ='Translog Model (NEW)'!J19 -> 1410.5662 | I17: ='X-Old Income Group'!L19 -> 1559042.1 | J17: ='X-Old Income Group'!M19 -> 35078.447 | K17: ='X-Old Income Group'!N19 -> 45170.372 | L17: ='X-Old Income Group'!O19 -> -10091.926 | M17: ='X-Old Income Group'!V19 -> 118.43665
C18: Low | D18: ='Translog Model (NEW)'!B20 -> 273 | E18: ='Translog Model (NEW)'!F20 -> 3612.1155 | F18: ='Translog Model (NEW)'!K20 -> 0.5 | G18: ='Translog Model (NEW)'!J20 -> 1806.0577 | I18: ='X-Old Income Group'!L20 -> 520444.34 | J18: ='X-Old Income Group'!M20 -> 11709.998 | K18: ='X-Old Income Group'!N20 -> 19290.142 | L18: ='X-Old Income Group'!O20 -> -7580.1439 | M18: ='X-Old Income Group'!V20 -> 81.562025
C19: Total | D19: ='X-Old Income Group'!B23 -> 1519 | E19: ='X-Old Income Group'!F23 -> 25431.561 | G19: ='X-Old Income Group'!J23 -> 2723.8685 | I19: ='X-Old Income Group'!L23 -> 7157205.6 | J19: ='X-Old Income Group'!M23 -> 161037.13 | K19: ='X-Old Income Group'!N23 -> 190193.1 | L19: ='X-Old Income Group'!O23 -> -29155.969
B20: Total | C20: High | D20: ='Translog Model (NEW)'!B27 -> 3287 | E20: ='Translog Model (NEW)'!F27 -> 8322.0406 | F20: ='Translog Model (NEW)'!K27 -> 0 | G20: ='Translog Model (NEW)'!J27 -> 0 | H20: - | I20: ='Translog Model (NEW)'!L27 -> 27068547 | J20: ='Translog Model (NEW)'!M27 -> 636110.86 | K20: ='Translog Model (NEW)'!N27 -> 541801.8 | L20: ='Translog Model (NEW)'!O27 -> 94309.066 | M20: ='X-Old Income Group'!V27 -> 116.0674 | N20: ='Translog Model (NEW)'!N3 -> 0.71907051 | O20: ='Translog Model (NEW)'!P3 -> 0.72465213
C21: Middle High | D21: ='Translog Model (NEW)'!B28 -> 5604 | E21: ='Translog Model (NEW)'!F28 -> 5557.3165 | F21: ='Translog Model (NEW)'!K28 -> 0.1 | G21: ='Translog Model (NEW)'!J28 -> 555.73165 | I21: ='Translog Model (NEW)'!L28 -> 27477881 | J21: ='Translog Model (NEW)'!M28 -> 645730.21 | K21: ='Translog Model (NEW)'!N28 -> 615375.61 | L21: ='Translog Model (NEW)'!O28 -> 30354.605 | M21: ='X-Old Income Group'!V28 -> 86.367925
C22: Middle Low | D22: ='Translog Model (NEW)'!B29 -> 3867 | E22: ='Translog Model (NEW)'!F29 -> 4001.8477 | F22: ='Translog Model (NEW)'!K29 -> 0.25 | G22: ='Translog Model (NEW)'!J29 -> 1000.4619 | I22: ='Translog Model (NEW)'!L29 -> 11197359 | J22: ='Translog Model (NEW)'!M29 -> 263137.93 | K22: ='Translog Model (NEW)'!N29 -> 304981.55 | L22: ='Translog Model (NEW)'!O29 -> -41843.617 | M22: ='X-Old Income Group'!V29 -> 69.723741
C23: Low | D23: ='Translog Model (NEW)'!B30 -> 2363 | E23: ='Translog Model (NEW)'!F30 -> 3838.9208 | F23: ='Translog Model (NEW)'!K30 -> 0.5 | G23: ='Translog Model (NEW)'!J30 -> 1919.4604 | I23: ='Translog Model (NEW)'!L30 -> 4262685 | J23: ='Translog Model (NEW)'!M30 -> 100173.1 | K23: ='Translog Model (NEW)'!N30 -> 178325.25 | L23: ='Translog Model (NEW)'!O30 -> -78152.153 | M23: ='X-Old Income Group'!V30 -> 75.633104
C24: Total | D24: ='X-Old Income Group'!B33 -> 15121 | E24: ='X-Old Income Group'!F33 -> 21772.674 | G24: ='X-Old Income Group'!J23 -> 2723.8685 | I24: ='X-Old Income Group'!L33 -> 74590307 | J24: ='X-Old Income Group'!M33 -> 1678281.9 | K24: ='X-Old Income Group'!N33 -> 1626758.1 | L24: ='X-Old Income Group'!O33 -> 51523.819
E26: Fuel Tax Burden Tk ($/HH/yr) | F26: Nk​* Tk | G26: Tax Share Sk | H26: Cum Tax Share Lk | I26: HH Share wk | J26: Cum HH Share Pk | L26: Gini Coefficient
C27: Without Q | D27: Urban | E27: ='Translog Model (NEW)'!V7 -> 164.61182 | F27: ='Translog Model (NEW)'!W7 -> 494000.08 | G27: ='Translog Model (NEW)'!X7 -> 0.40155505 | H27: ='Translog Model (NEW)'!Y7 -> 0.40155505 | I27: ='Translog Model (NEW)'!Z7 -> 0.22062932 | J27: ='Translog Model (NEW)'!AA7 -> 0.22062932 | K27: ='Translog Model (NEW)'!AB7 -> 0.088594816 | L27: ='Translog Model (NEW)'!AC7 -> 0.71862867
E28: ='Translog Model (NEW)'!V8 -> 95.69043 | F28: ='Translog Model (NEW)'!W8 -> 483523.74 | G28: ='Translog Model (NEW)'!X8 -> 0.3930392 | H28: ='Translog Model (NEW)'!Y8 -> 0.79459425 | I28: ='Translog Model (NEW)'!Z8 -> 0.37148949 | J28: ='Translog Model (NEW)'!AA8 -> 0.59211881 | K28: ='Translog Model (NEW)'!AB8 -> 0.14600993
E29: ='Translog Model (NEW)'!V9 -> 53.785527 | F29: ='Translog Model (NEW)'!W9 -> 185990.35 | G29: ='Translog Model (NEW)'!X9 -> 0.15118492 | H29: ='Translog Model (NEW)'!Y9 -> 0.94577917 | I29: ='Translog Model (NEW)'!Z9 -> 0.25422732 | J29: ='Translog Model (NEW)'!AA9 -> 0.84634613 | K29: ='Translog Model (NEW)'!AB9 -> 0.038435338
E30: ='Translog Model (NEW)'!V10 -> 31.915509 | F30: ='Translog Model (NEW)'!W10 -> 66703.415 | G30: ='Translog Model (NEW)'!X10 -> 0.054220827 | H30: ='Translog Model (NEW)'!Y10 -> 1 | I30: ='Translog Model (NEW)'!Z10 -> 0.15365387 | J30: ='Translog Model (NEW)'!AA10 -> 1 | K30: ='Translog Model (NEW)'!AB10 -> 0.0083312401
D31: Rural | E31: ='Translog Model (NEW)'!V17 -> 162.1324 | F31: ='Translog Model (NEW)'!W17 -> 46369.866 | G31: ='Translog Model (NEW)'!X17 -> 0.37310929 | H31: ='Translog Model (NEW)'!Y17 -> 0.37310929 | I31: ='Translog Model (NEW)'!Z17 -> 0.18828176 | J31: ='Translog Model (NEW)'!AA17 -> 0.18828176 | K31: ='Translog Model (NEW)'!AB17 -> 0.070249675 | L31: ='Translog Model (NEW)'!AC17 -> 0.72217445
E32: ='Translog Model (NEW)'!V18 -> 96.561271 | F32: ='Translog Model (NEW)'!W18 -> 53205.261 | G32: ='Translog Model (NEW)'!X18 -> 0.42810943 | H32: ='Translog Model (NEW)'!Y18 -> 0.80121871 | I32: ='Translog Model (NEW)'!Z18 -> 0.36273864 | J32: ='Translog Model (NEW)'!AA18 -> 0.55102041 | K32: ='Translog Model (NEW)'!AB18 -> 0.15529183
E33: ='Translog Model (NEW)'!V19 -> 56.196988 | F33: ='Translog Model (NEW)'!W19 -> 22984.568 | G33: ='Translog Model (NEW)'!X19 -> 0.18494243 | H33: ='Translog Model (NEW)'!Y19 -> 0.98616115 | I33: ='Translog Model (NEW)'!Z19 -> 0.26925609 | J33: ='Translog Model (NEW)'!AA19 -> 0.8202765 | K33: ='Translog Model (NEW)'!AB19 -> 0.049796876
E34: ='Translog Model (NEW)'!V20 -> 6.2999527 | F34: ='Translog Model (NEW)'!W20 -> 1719.8871 | G34: ='Translog Model (NEW)'!X20 -> 0.013838855 | H34: ='Translog Model (NEW)'!Y20 -> 1 | I34: ='Translog Model (NEW)'!Z20 -> 0.1797235 | J34: ='Translog Model (NEW)'!AA20 -> 1 | K34: ='Translog Model (NEW)'!AB20 -> 0.0024871675
D35: Total | E35: ='Translog Model (NEW)'!V27 -> 164.39609 | F35: ='Translog Model (NEW)'!W27 -> 540369.95 | G35: ='Translog Model (NEW)'!X27 -> 0.39894505 | H35: ='Translog Model (NEW)'!Y27 -> 0.39894505 | I35: ='Translog Model (NEW)'!Z27 -> 0.2173798 | J35: ='Translog Model (NEW)'!AA27 -> 0.2173798 | K35: ='Translog Model (NEW)'!AB27 -> 0.086722597 | L35: ='Translog Model (NEW)'!AC27 -> 0.71907051
E36: ='Translog Model (NEW)'!V28 -> 95.776054 | F36: ='Translog Model (NEW)'!W28 -> 536729 | G36: ='Translog Model (NEW)'!X28 -> 0.39625701 | H36: ='Translog Model (NEW)'!Y28 -> 0.79520207 | I36: ='Translog Model (NEW)'!Z28 -> 0.37061041 | J36: ='Translog Model (NEW)'!AA28 -> 0.58799021 | K36: ='Translog Model (NEW)'!AB28 -> 0.14685697
E37: ='Translog Model (NEW)'!V29 -> 54.04058 | F37: ='Translog Model (NEW)'!W29 -> 208974.92 | G37: ='Translog Model (NEW)'!X29 -> 0.15428229 | H37: ='Translog Model (NEW)'!Y29 -> 0.94948435 | I37: ='Translog Model (NEW)'!Z29 -> 0.25573705 | J37: ='Translog Model (NEW)'!AA29 -> 0.84372727 | K37: ='Translog Model (NEW)'!AB29 -> 0.039455698
E38: ='Translog Model (NEW)'!V30 -> 28.956116 | F38: ='Translog Model (NEW)'!W30 -> 68423.302 | G38: ='Translog Model (NEW)'!X30 -> 0.050515647 | H38: ='Translog Model (NEW)'!Y30 -> 1 | I38: ='Translog Model (NEW)'!Z30 -> 0.15627273 | J38: ='Translog Model (NEW)'!AA30 -> 1 | K38: ='Translog Model (NEW)'!AB30 -> 0.0078942183
C39: With Q | D39: Urban | E39: ='Translog Model (NEW)'!AF7 -> 163.16047 | F39: ='Translog Model (NEW)'!AG7 -> 489644.56 | G39: ='Translog Model (NEW)'!AH7 -> 0.33760368 | H39: ='Translog Model (NEW)'!AI7 -> 0.33760368 | I39: ='Translog Model (NEW)'!AJ7 -> 0.22062932 | J39: ='Translog Model (NEW)'!AK7 -> 0.22062932 | K39: ='Translog Model (NEW)'!AL7 -> 0.074485269 | L39: ='Translog Model (NEW)'!AM7 -> 0.72433365
E40: ='Translog Model (NEW)'!AF8 -> 107.23577 | F40: ='Translog Model (NEW)'!AG8 -> 541862.32 | G40: ='Translog Model (NEW)'!AH8 -> 0.37360716 | H40: ='Translog Model (NEW)'!AI8 -> 0.71121083 | I40: ='Translog Model (NEW)'!AJ8 -> 0.37148949 | J40: ='Translog Model (NEW)'!AK8 -> 0.59211881 | K40: ='Translog Model (NEW)'!AL8 -> 0.13879113
E41: ='Translog Model (NEW)'!AF9 -> 75.133364 | F41: ='Translog Model (NEW)'!AG9 -> 259811.17 | G41: ='Translog Model (NEW)'!AH9 -> 0.17913649 | H41: ='Translog Model (NEW)'!AI9 -> 0.89034732 | I41: ='Translog Model (NEW)'!AJ9 -> 0.25422732 | J41: ='Translog Model (NEW)'!AK9 -> 0.84634613 | K41: ='Translog Model (NEW)'!AL9 -> 0.04554139
E42: ='Translog Model (NEW)'!AF10 -> 76.093353 | F42: ='Translog Model (NEW)'!AG10 -> 159035.11 | G42: ='Translog Model (NEW)'!AH10 -> 0.10965268 | H42: ='Translog Model (NEW)'!AI10 -> 1 | I42: ='Translog Model (NEW)'!AJ10 -> 0.15365387 | J42: ='Translog Model (NEW)'!AK10 -> 1 | K42: ='Translog Model (NEW)'!AL10 -> 0.016848559
D43: Rural | E43: ='Translog Model (NEW)'!AF17 -> 182.36797 | F43: ='Translog Model (NEW)'!AG17 -> 52157.24 | G43: ='Translog Model (NEW)'!AH17 -> 0.2743226 | H43: ='Translog Model (NEW)'!AI17 -> 0.2743226 | I43: ='Translog Model (NEW)'!AJ17 -> 0.18828176 | J43: ='Translog Model (NEW)'!AK17 -> 0.18828176 | K43: ='Translog Model (NEW)'!AL17 -> 0.051649943 | L43: ='Translog Model (NEW)'!AM17 -> 0.72589612
...

Sheet Translog Model (NEW)
A1: **current tax rate/mile r ($/mi) = | D1: 0.01954489 | F1: Current Total Revenue R ($) | H1: =N13+N23 -> 1623091 | L1: Urban Gini Index (G) = | N1: =AC7 -> 0.71862867 | O1: Old Gini Index (No free mileage) | P1: =AM7 -> 0.72433365 | Q1: =N1/P1-1 -> -0.0078761742
A2: **optimized tax rate/mile r ($/mi) = | D2: 0.0235 | F2: Optimized Total Revenue R ($) | H2: =M13+M23 -> 1645152.1 | L2: Rural Gini Index (G) = | N2: =AC17 -> 0.72217445 | P2: =AM17 -> 0.72589612 | Q2: =N2/P2-1 -> -0.005126999
F3: ∆ ($ ) | G3: + | H3: =O13+O23 -> 22061.101 | I3: =H2/H1-1 -> 0.01359203 | L3: Total Gini Index (G) = | N3: =AC27 -> 0.71907051 | P3: =AM27 -> 0.72465213 | Q3: =N3/P3-1 -> -0.0077024777 | S3: Free Mileage Quota Q (mi/HH/yr) | V3: Gini Index with Free Mileage Quota | AF3: Old Gini Index without Mileage Quota
J4: Auto Updated | K4: Adjusted parameter | S4: Adjusted Q | T4: Auto Updated
A5: Urban | H5: Cum | I5: Cum | J5: TBD | K5: TBD | L5: Cum | M5: Cum | N5: Cum | Q5: TBD | V5: TBD | AF5: TBD | AS5: NEW | AV5: OLD
A6: Income Group | B6: HH (#) | C6: Current Weekly VMT (mi/wk) | D6: Current Annual VMT (mi/HH/yr) | E6: Adjusted Weekly VMT (mi/HH/wk) | F6: Adjusted VMT (mi/HH/yr) | H6: Current VMT (mi/HH/yr) | I6: Adjusted VMT (mi/HH/yr) | J6: Free Mileage Quota Q (mi/HH/yr) | K6: Gamma γ | L6: VMT (taxable) | M6: Adjusted Revenue R ($) | N6: Current Revenue R ($) | O6: ∆ ($ ) | Q6: Extra Mileage ∆g | S6: Q after ß | T6: beta ß | V6: Mileage Tax Burden Tˉk ($/HH/yr) | W6: Nk​*Tˉk | X6: Tax Share Sk | Y6: Cum Tax Share Lk | Z6: HH Share wk | AA6: Cum HH Share Pk | AC6: Gini Index | AF6: Fuel Tax Burden Tˉk ($/HH/yr) | AG6: Nk​*Tˉk | AH6: Tax Share Sk | AI6: Cum Tax Share Lk | AJ6: HH Share wk | AK6: Cum HH Share Pk | AM6: Gini Index | AR6: Urban | AS6: Cum Tax Share Lk | AT6: Cum HH Share Pk | AV6: Cum Tax Share Lk | AW6: Cum HH Share Pk
A7: H | B7: 3001 | C7: 160.53819 | D7: =C7*52 -> 8347.9859 | E7: 158.2806 | F7: =52*E7 -> 8230.5912 | H7: =C7*52*B7 -> 25052306 | I7: =F7*B7 -> 24700004 | J7: =K7*F7 -> 0 | K7: 0 | L7: =B7*(F7-J7-Q7) -> 24700004 | M7: =L7*$D$2 -> 580450.1 | N7: =H7*$D$1 -> 489644.56 | O7: =M7-N7 -> 90805.538 | Q7: 0 | S7: 0 | T7: =S7/F7 -> 0 | U7: 164.61182 | V7: =U7-J7*$D$2 -> 164.61182 | W7: =B7*V7 -> 494000.08 | X7: =W7/$W$13 -> 0.40155505 | Y7: =X7 -> 0.40155505 | Z7: =B7/$B$13 -> 0.22062932 | AA7: =Z7 -> 0.22062932 | AB7: =Y7*AA7 -> 0.088594816 | AC7: =1-AB13 -> 0.71862867 | AD7: =Y7*AA7 -> 0.088594816 | AF7: =N7/B7 -> 163.16047 | AG7: =B7*AF7 -> 489644.56 | AH7: =AG7/$AG$13 -> 0.33760368 | AI7: =AH7 -> 0.33760368 | AJ7: =B7/$B$13 -> 0.22062932 | AK7: =AJ7 -> 0.22062932 | AL7: =AI7*AK7 -> 0.074485269 | AM7: =1-AL13 -> 0.72433365 | AN7: =AI7*AK7 -> 0.074485269 | AS7: =Y7 -> 0.40155505 | AT7: =AA7 -> 0.22062932 | AV7: =AI7 -> 0.33760368 | AW7: =AK7 -> 0.22062932
A8: MH | B8: 5053 | C8: 105.5123 | D8: =C8*52 -> 5486.6395 | E8: 104.26066 | F8: =52*E8 -> 5421.5541 | H8: =C8*52*B8 -> 27723989 | I8: =F8*B8 -> 27395113 | J8: =K8*F8 -> 542.15541 | K8: 0.1 | L8: =B8*(F8-J8-Q8) -> 24655602 | M8: =L8*$D$2 -> 579406.64 | N8: =H8*$D$1 -> 541862.32 | O8: =M8-N8 -> 37544.317 | Q8: 0 | S8: 500 | T8: =S8/F8 -> 0.092224478 | U8: 108.43108 | V8: =U8-J8*$D$2 -> 95.69043 | W8: =B8*V8 -> 483523.74 | X8: =W8/$W$13 -> 0.3930392 | Y8: =X8+Y7 -> 0.79459425 | Z8: =B8/$B$13 -> 0.37148949 | AA8: =Z8+AA7 -> 0.59211881 | AB8: =(Y8-Y7)*(AA8-AA7) -> 0.14600993 | AD8: =Y8*AA8 -> 0.4704942 | AF8: =N8/B8 -> 107.23577 | AG8: =B8*AF8 -> 541862.32 | AH8: =AG8/$AG$13 -> 0.37360716 | AI8: =AH8+AI7 -> 0.71121083 | AJ8: =B8/$B$13 -> 0.37148949 | AK8: =AJ8+AK7 -> 0.59211881 | AL8: =(AI8-AI7)*(AK8-AK7) -> 0.13879113 | AN8: =AI8*AK8 -> 0.42112131 | AS8: =Y8 -> 0.79459425 | AT8: =AA8 -> 0.59211881 | AV8: =AI8 -> 0.71121083 | AW8: =AK8 -> 0.59211881
A9: ML | B9: 3458 | C9: 73.925839 | D9: =C9*52 -> 3844.1436 | E9: 73.227403 | F9: =52*E9 -> 3807.8249 | H9: =C9*52*B9 -> 13293049 | I9: =F9*B9 -> 13167459 | J9: =K9*F9 -> 951.95624 | K9: 0.25 | L9: =B9*(F9-J9-Q9) -> 9875594 | M9: =L9*$D$2 -> 232076.46 | N9: =H9*$D$1 -> 259811.17 | O9: =M9-N9 -> -27734.715 | Q9: 0 | S9: 1000 | T9: =S9/F9 -> 0.26261711 | U9: 76.156499 | V9: =U9-J9*$D$2 -> 53.785527 | W9: =B9*V9 -> 185990.35 | X9: =W9/$W$13 -> 0.15118492 | Y9: =X9+Y8 -> 0.94577917 | Z9: =B9/$B$13 -> 0.25422732 | AA9: =Z9+AA8 -> 0.84634613 | AB9: =(Y9-Y8)*(AA9-AA8) -> 0.038435338 | AD9: =Y9*AA9 -> 0.80045654 | AF9: =N9/B9 -> 75.133364 | AG9: =B9*AF9 -> 259811.17 | AH9: =AG9/$AG$13 -> 0.17913649 | AI9: =AH9+AI8 -> 0.89034732 | AJ9: =B9/$B$13 -> 0.25422732 | AK9: =AJ9+AK8 -> 0.84634613 | AL9: =(AI9-AI8)*(AK9-AK8) -> 0.04554139 | AN9: =AI9*AK9 -> 0.75354201 | AS9: =Y9 -> 0.94577917 | AT9: =AA9 -> 0.84634613 | AV9: =AI9 -> 0.89034732 | AW9: =AK9 -> 0.84634613
A10: L | B10: 2090 | C10: 74.870399 | D10: =C10*52 -> 3893.2607 | E10: 74.395127 | F10: =52*E10 -> 3868.5466 | H10: =C10*52*B10 -> 8136915 | I10: =F10*B10 -> 8085262.4 | J10: =K10*F10 -> 1934.2733 | K10: 0.5 | L10: =B10*(F10-J10-Q10) -> 4042631.2 | M10: =L10*$D$2 -> 95001.833 | N10: =H10*$D$1 -> 159035.11 | O10: =M10-N10 -> -64033.275 | Q10: 0 | S10: 2000 | T10: =S10/F10 -> 0.51699002 | U10: 77.370932 | V10: =U10-J10*$D$2 -> 31.915509 | W10: =B10*V10 -> 66703.415 | X10: =W10/$W$13 -> 0.054220827 | Y10: =X10+Y9 -> 1 | Z10: =B10/$B$13 -> 0.15365387 | AA10: =Z10+AA9 -> 1 | AB10: =(Y10-Y9)*(AA10-AA9) -> 0.0083312401 | AD10: =Y10*AA10 -> 1 | AF10: =N10/B10 -> 76.093353 | AG10: =B10*AF10 -> 159035.11 | AH10: =AG10/$AG$13 -> 0.10965268 | AI10: =AH10+AI9 -> 1 | AJ10: =B10/$B$13 -> 0.15365387 | AK10: =AJ10+AK9 -> 1 | AL10: =(AI10-AI9)*(AK10-AK9) -> 0.016848559 | AN10: =AI10*AK10 -> 1 | AS10: =Y10 -> 1 | AT10: =AA10 -> 1 | AV10: =AI10 -> 1 | AW10: =AK10 -> 1
A13: Ntotal | B13: =SUM(B7:B12) -> 13602 | E13: =SUM(E7:E10)/4 -> 102.54095 | F13: =SUM(F7:F12) -> 21328.517 | H13: =SUM(H7:H12) -> 74206259 | I13: =SUM(I7:I12) -> 73347838 | J13: =SUM(J7:J12) -> 3428.385 | L13: =SUM(L7:L12) -> 63273831 | M13: =L13*$D$2 -> 1486935 | N13: =I13*$D$1 -> 1433575.4 | O13: =M13-N13 -> 53359.6 | Q13: =SUM(Q7:Q12) -> 0 | S13: =SUM(S7:S12) -> 3500 | W13: =SUM(W7:W10) -> 1230217.6 | AB13: =SUM(AB7:AB10) -> 0.28137133 | AG13: =SUM(AG7:AG12) -> 1450353.2 | AL13: =SUM(AL7:AL12) -> 0.27566635
A15: Rural | AS15: NEW | AV15: OLD
A16: Income Group | B16: HH (#) | C16: Current Mean VMT (mi/d) | D16: Current Annual (mi/HH/yr) | E16: Predicted Weekly VMT (mi/HH/wk) | F16: Predicted VMT (mi/HH/yr) | H16: Current VMT (mi/HH/yr) | I16: VMT (mi/HH/yr) | J16: Free Mileage Quota Q (mi/HH/yr) | K16: Gamma γ | L16: VMT (taxable) | M16: Optimized Revenue R ($) | N16: Current Revenue R ($) | O16: ∆ ($ ) | Q16: ∆g | S16: Q after ß | T16: beta ß | V16: Fuel Tax Burden Tˉk ($/HH/yr) | W16: Nk​*Tˉk | X16: Tax Share Sk | Y16: Cum Tax Share Lk | Z16: HH Share wk | AA16: Cum HH Share Pk | AC16: Gini Index | AF16: Fuel Tax Burden Tˉk ($/HH/yr) | AG16: Nk​*Tˉk | AH16: Tax Share Sk | AI16: Cum Tax Share Lk | AJ16: HH Share wk | AK16: Cum HH Share Pk | AM16: Gini Index | AR16: Rural | AS16: Cum Tax Share Lk | AT16: Cum HH Share Pk | AV16: Cum Tax Share Lk | AW16: Cum HH Share Pk
A17: H | B17: 286 | C17: 179.437 | D17: =C17*52 -> 9330.7238 | E17: 178.49269 | F17: =52*E17 -> 9281.62 | H17: =C17*52*B17 -> 2668587 | I17: =F17*B17 -> 2654543.3 | J17: =K17*F17 -> 0 | K17: 0 | L17: =B17*(F17-J17-Q17) -> 2368543.3 | M17: =L17*$D$2 -> 55660.768 | N17: =H17*$D$1 -> 52157.24 | O17: =M17-N17 -> 3503.5281 | Q17: 1000 | S17: 0 | T17: =S17/F17 -> 0 | U17: 185.6324 | V17: =U17-$D$2*J17-Q17*$D$2 -> 162.1324 | W17: =B17*V17 -> 46369.866 | X17: =W17/$W$23 -> 0.37310929 | Y17: =X17 -> 0.37310929 | Z17: =B17/$B$23 -> 0.18828176 | AA17: =Z17 -> 0.18828176 | AB17: =Y17*AA17 -> 0.070249675 | AC17: =1-AB23 -> 0.72217445 | AD17: =Y17*AA17 -> 0.070249675 | AF17: =N17/B17 -> 182.36797 | AG17: =B17*AF17 -> 52157.24 | AH17: =AG17/$AG$23 -> 0.2743226 | AI17: =AH17 -> 0.2743226 | AJ17: =B17/$B$23 -> 0.18828176 | AK17: =AJ17 -> 0.18828176 | AL17: =AI17*AK17 -> 0.051649943 | AM17: =1-AL23 -> 0.72589612 | AN17: =AI17*AK17 -> 0.051649943 | AS17: =Y17 -> 0.37310929 | AT17: =AA17 -> 0.18828176 | AV17: =AI17 -> 0.2743226 | AW17: =AK17 -> 0.18828176
A18: MH | B18: 551 | C18: 131.27367 | D18: =C18*52 -> 6826.2311 | E18: 130.8142 | F18: =52*E18 -> 6802.3383 | H18: =C18*52*B18 -> 3761253.3 | I18: =F18*B18 -> 3748088.4 | J18: =K18*F18 -> 680.23383 | K18: 0.1 | L18: =B18*(F18-J18-Q18) -> 2822279.6 | M18: =L18*$D$2 -> 66323.57 | N18: =H18*$D$1 -> 73513.283 | O18: =M18-N18 -> -7189.7127 | Q18: 1000 | S18: 1000 | T18: =S18/F18 -> 0.14700827 | U18: 136.04677 | V18: =U18-$D$2*J18-Q18*$D$2 -> 96.561271 | W18: =B18*V18 -> 53205.261 | X18: =W18/$W$23 -> 0.42810943 | Y18: =X18+Y17 -> 0.80121871 | Z18: =B18/$B$23 -> 0.36273864 | AA18: =Z18+AA17 -> 0.55102041 | AB18: =(Y18-Y17)*(AA18-AA17) -> 0.15529183 | AD18: =Y18*AA18 -> 0.44148786 | AF18: =N18/B18 -> 133.41794 | AG18: =B18*AF18 -> 73513.283 | AH18: =AG18/$AG$23 -> 0.38664536 | AI18: =AH18+AI17 -> 0.66096796 | AJ18: =B18/$B$23 -> 0.36273864 | AK18: =AJ18+AK17 -> 0.55102041 | AL18: =(AI18-AI17)*(AK18-AK17) -> 0.14025121 | AN18: =AI18*AK18 -> 0.36420683 | AS18: =Y18 -> 0.80121871 | AT18: =AA18 -> 0.55102041 | AV18: =AI18 -> 0.66096796 | AW18: =AK18 -> 0.55102041
A19: ML | B19: 409 | C19: 108.66603 | D19: =C19*52 -> 5650.6334 | E19: 108.50509 | F19: =52*E19 -> 5642.2646 | H19: =C19*52*B19 -> 2311109.1 | I19: =F19*B19 -> 2307686.2 | J19: =K19*F19 -> 1410.5662 | K19: 0.25 | L19: =B19*(F19-J19-Q19) -> 1321764.7 | M19: =L19*$D$2 -> 31061.47 | N19: =H19*$D$1 -> 45170.372 | O19: =M19-N19 -> -14108.902 | Q19: 1000 | S19: 2000 | T19: =S19/F19 -> 0.3544676 | U19: 112.84529 | V19: =U19-$D$2*J19-Q19*$D$2 -> 56.196988 | W19: =B19*V19 -> 22984.568 | X19: =W19/$W$23 -> 0.18494243 | Y19: =X19+Y18 -> 0.98616115 | Z19: =B19/$B$23 -> 0.26925609 | AA19: =Z19+AA18 -> 0.8202765 | AB19: =(Y19-Y18)*(AA19-AA18) -> 0.049796876 | AD19: =Y19*AA19 -> 0.80892481 | AF19: =N19/B19 -> 110.44101 | AG19: =B19*AF19 -> 45170.372 | AH19: =AG19/$AG$23 -> 0.23757495 | AI19: =AH19+AI18 -> 0.89854291 | AJ19: =B19/$B$23 -> 0.26925609 | AK19: =AJ19+AK18 -> 0.8202765 | AL19: =(AI19-AI18)*(AK19-AK18) -> 0.063968503 | AN19: =AI19*AK19 -> 0.73705363 | AS19: =Y19 -> 0.98616115 | AT19: =AA19 -> 0.8202765 | AV19: =AI19 -> 0.89854291 | AW19: =AK19 -> 0.8202765
A20: L | B20: 273 | C20: 69.524231 | D20: =C20*52 -> 3615.26 | E20: 69.463759 | F20: =52*E20 -> 3612.1155 | H20: =C20*52*B20 -> 986965.98 | I20: =F20*B20 -> 986107.53 | J20: =K20*F20 -> 1806.0577 | K20: 0.5 | L20: =B20*(F20-J20-Q20) -> 220053.76 | M20: =L20*$D$2 -> 5171.2634 | N20: =H20*$D$1 -> 19290.142 | O20: =M20-N20 -> -14118.878 | Q20: 1000 | S20: 3000 | T20: =S20/F20 -> 0.83053823 | U20: 72.24231 | V20: =U20-$D$2*J20-Q20*$D$2 -> 6.2999527 | W20: =B20*V20 -> 1719.8871 | X20: =W20/$W$23 -> 0.013838855 | Y20: =X20+Y19 -> 1 | Z20: =B20/$B$23 -> 0.1797235 | AA20: =Z20+AA19 -> 1 | AB20: =(Y20-Y19)*(AA20-AA19) -> 0.0024871675 | AD20: =Y20*AA20 -> 1 | AF20: =N20/B20 -> 70.659859 | AG20: =B20*AF20 -> 19290.142 | AH20: =AG20/$AG$23 -> 0.10145709 | AI20: =AH20+AI19 -> 1 | AJ20: =B20/$B$23 -> 0.1797235 | AK20: =AJ20+AK19 -> 1 | AL20: =(AI20-AI19)*(AK20-AK19) -> 0.018234223 | AN20: =AI20*AK20 -> 1 | AS20: =Y20 -> 1 | AT20: =AA20 -> 1 | AV20: =AI20 -> 1 | AW20: =AK20 -> 1
B23: =SUM(B17:B22) -> 1519 | E23: =SUM(E17:E20)/4 -> 121.81893 | F23: =SUM(F17:F22) -> 25338.338 | H23: =SUM(H17:H22) -> 9727915.4 | I23: =SUM(I17:I22) -> 9696425.5 | J23: =SUM(J17:J22) -> 3896.8577 | L23: =SUM(L17:L22) -> 6732641.3 | M23: =L23*$D$2 -> 158217.07 | N23: =I23*$D$1 -> 189515.57 | O23: =M23-N23 -> -31298.498 | Q23: =SUM(Q17:Q22) -> 4000 | S23: =SUM(S17:S22) -> 6000 | W23: =SUM(W17:W22) -> 124279.58 | AB23: =SUM(AB17:AB22) -> 0.27782555 | AG23: =SUM(AG17:AG22) -> 190131.04 | AL23: =SUM(AL17:AL22) -> 0.27410388
A25: Total | AS25: NEW | AV25: OLD
A26: Income Group | B26: HH (#) | C26: Current Mean VMT (mi/d) | D26: Current Annual (mi/HH/yr) | E26: Predicted Weekly VMT (mi/HH/wk) | F26: Predicted VMT (mi/HH/yr) | H26: Current VMT (mi/HH/yr) | I26: Predicted VMT (mi/HH/yr) | J26: Free Mileage Quota Q (mi/HH/yr) | K26: Gamma γ | L26: VMT (taxable) | M26: Optimized Revenue R ($) | N26: Current Revenue R ($) | O26: ∆ ($ ) | Q26: Extra Mileage ∆g | S26: Q after ß | T26: beta ß | V26: Fuel Tax Burden Tˉk ($/HH/yr) | W26: Nk​*Tˉk | X26: Tax Share Sk | Y26: Cum Tax Share Lk | Z26: HH Share wk | AA26: Cum HH Share Pk | AC26: Gini Index | AF26: Fuel Tax Burden Tˉk ($/HH/yr) | AG26: Nk​*Tˉk | AH26: Tax Share Sk | AI26: Cum Tax Share Lk | AJ26: HH Share wk | AK26: Cum HH Share Pk | AM26: Gini Index | AR26: Total | AS26: Cum Tax Share Lk | AT26: Cum HH Share Pk | AV26: Cum Tax Share Lk | AW26: Cum HH Share Pk
A27: H | B27: =(B7+B17) -> 3287 | C27: =(C7*B7+C17*B17)/B27 -> 162.18256 | D27: =C27*52 -> 8433.4934 | E27: =(E7*B7+E17*B17)/B27 -> 160.03924 | F27: =52*E27 -> 8322.0406 | H27: =C27*52*B27 -> 27720893 | I27: =F27*B27 -> 27354547 | J27: =K27*F27 -> 0 | K27: 0 | L27: =B27*(F27-J27-Q27)-B17*Q17 -> 27068547 | M27: =M7+M17 -> 636110.86 | N27: =H27*$D$1 -> 541801.8 | O27: =M27-N27 -> 94309.066 | S27: 0 | T27: 0 | V27: =(V7*B7+V17*B17)/B27 -> 164.39609 | W27: =B27*V27 -> 540369.95 | X27: =W27/$W$33 -> 0.39894505 | Y27: =X27 -> 0.39894505 | Z27: =B27/$B$33 -> 0.2173798 | AA27: =Z27 -> 0.2173798 | AB27: =Y27*AA27 -> 0.086722597 | AC27: =1-AB33 -> 0.71907051 | AD27: =Y27*AA27 -> 0.086722597 | AF27: =N27/B27 -> 164.8317 | AG27: =B27*AF27 -> 541801.8 | AH27: =AG27/$AG$33 -> 0.33026944 | AI27: =AH27 -> 0.33026944 | AJ27: =B27/$B$33 -> 0.2173798 | AK27: =AJ27 -> 0.2173798 | AL27: =AI27*AK27 -> 0.071793906 | AM27: =1-AL33 -> 0.72465213 | AN27: 0.07448527 | AS27: =Y27 -> 0.39894505 | AT27: =AA27 -> 0.2173798 | AV27: =AI27 -> 0.33026944 | AW27: =AK27 -> 0.2173798
A28: MH | B28: =(B8+B18) -> 5604 | C28: =(C8*B8+C18*B18)/B28 -> 108.04522 | D28: =C28*52 -> 5618.3517 | E28: =(E8*B8+E18*B18)/B28 -> 106.87147 | F28: =52*E28 -> 5557.3165 | H28: =C28*52*B28 -> 31485243 | I28: =F28*B28 -> 31143201 | J28: =K28*F28 -> 555.73165 | K28: 0.1 | L28: =B28*(F28-J28-Q28)-B18*Q18 -> 27477881 | M28: =M8+M18 -> 645730.21 | N28: =H28*$D$1 -> 615375.61 | O28: =M28-N28 -> 30354.605 | S28: 500 | T28: 0.09 | V28: =(V8*B8+V18*B18)/B28 -> 95.776054 | W28: =B28*V28 -> 536729 | X28: =W28/$W$33 -> 0.39625701 | Y28: =X28+Y27 -> 0.79520207 | Z28: =B28/$B$33 -> 0.37061041 | AA28: =Z28+AA27 -> 0.58799021 | AB28: =(Y28-Y27)*(AA28-AA27) -> 0.14685697 | AD28: =Y28*AA28 -> 0.46757103 | AF28: =N28/B28 -> 109.81007 | AG28: =B28*AF28 -> 615375.61 | AH28: =AG28/$AG$33 -> 0.37511828 | AI28: =AH28+AI27 -> 0.70538772 | AJ28: =B28/$B$33 -> 0.37061041 | AK28: =AJ28+AK27 -> 0.58799021 | AL28: =(AI28-AI27)*(AK28-AK27) -> 0.13902274 | AN28: 0.42112131 | AS28: =Y28 -> 0.79520207 | AT28: =AA28 -> 0.58799021 | AV28: =AI28 -> 0.70538772 | AW28: =AK28 -> 0.58799021
A29: ML | B29: =(B9+B19) -> 3867 | C29: =(C9*B9+C19*B19)/B29 -> 77.600196 | D29: =C29*52 -> 4035.2102 | E29: =(E9*B9+E19*B19)/B29 -> 76.958609 | F29: =52*E29 -> 4001.8477 | H29: =C29*52*B29 -> 15604158 | I29: =F29*B29 -> 15475145 | J29: =K29*F29 -> 1000.4619 | K29: 0.25 | L29: =B29*(F29-J29-Q29)-B19*Q19 -> 11197359 | M29: =M9+M19 -> 263137.93 | N29: =H29*$D$1 -> 304981.55 | O29: =M29-N29 -> -41843.617 | S29: 1000 | T29: 0.26 | V29: =(V9*B9+V19*B19)/B29 -> 54.04058 | W29: =B29*V29 -> 208974.92 | X29: =W29/$W$33 -> 0.15428229 | Y29: =X29+Y28 -> 0.94948435 | Z29: =B29/$B$33 -> 0.25573705 | AA29: =Z29+AA28 -> 0.84372727 | AB29: =(Y29-Y28)*(AA29-AA28) -> 0.039455698 | AD29: =Y29*AA29 -> 0.80110584 | AF29: =N29/B29 -> 78.867739 | AG29: =B29*AF29 -> 304981.55 | AH29: =AG29/$AG$33 -> 0.18590947 | AI29: =AH29+AI28 -> 0.89129719 | AJ29: =B29/$B$33 -> 0.25573705 | AK29: =AJ29+AK28 -> 0.84372727 | AL29: =(AI29-AI28)*(AK29-AK28) -> 0.04754394 | AN29: 0.75354201 | AS29: =Y29 -> 0.94948435 | AT29: =AA29 -> 0.84372727 | AV29: =AI29 -> 0.89129719 | AW29: =AK29 -> 0.84372727
A30: L | B30: =(B10+B20) -> 2363 | C30: =(C10*B10+C20*B20)/B30 -> 74.25275 | D30: =C30*52 -> 3861.143 | E30: =(E10*B10+E20*B20)/B30 -> 73.825401 | F30: =52*E30 -> 3838.9208 | H30: =C30*52*B30 -> 9123880.9 | I30: =F30*B30 -> 9071369.9 | J30: =K30*F30 -> 1919.4604 | K30: 0.5 | L30: =B30*(F30-J30-Q30)-B20*Q20 -> 4262685 | M30: =M10+M20 -> 100173.1 | N30: =H30*$D$1 -> 178325.25 | O30: =M30-N30 -> -78152.153 | S30: 2000 | T30: 0.51 | V30: =(V10*B10+V20*B20)/B30 -> 28.956116 | W30: =B30*V30 -> 68423.302 | X30: =W30/$W$33 -> 0.050515647 | Y30: =X30+Y29 -> 1 | Z30: =B30/$B$33 -> 0.15627273 | AA30: =Z30+AA29 -> 1 | AB30: =(Y30-Y29)*(AA30-AA29) -> 0.0078942183 | AD30: =Y30*AA30 -> 1 | AF30: =N30/B30 -> 75.465616 | AG30: =B30*AF30 -> 178325.25 | AH30: =AG30/$AG$33 -> 0.10870281 | AI30: =AH30+AI29 -> 1 | AJ30: =B30/$B$33 -> 0.15627273 | AK30: =AJ30+AK29 -> 1 | AL30: =(AI30-AI29)*(AK30-AK29) -> 0.016987286 | AN30: 1 | AS30: =Y30 -> 1 | AT30: =AA30 -> 1 | AV30: =AI30 -> 1 | AW30: =AK30 -> 1
B33: =SUM(B27:B32) -> 15121 | E33: =SUM(E27:E30)/4 -> 104.42368 | F33: =SUM(F27:F32) -> 21720.126 | H33: =SUM(H27:H32) -> 83934174 | I33: =SUM(I27:I32) -> 83044264 | J33: =SUM(J27:J32) -> 3475.654 | L33: =SUM(L27:L30) -> 70006472 | M33: =L33*$D$2 -> 1645152.1 | N33: =I33*$D$1 -> 1623091 | O33: =M33-N33 -> 22061.101 | Q33: =SUM(Q27:Q32) -> 0 | W33: =SUM(W27:W32) -> 1354497.2 | AB33: =SUM(AB27:AB32) -> 0.28092949 | AG33: =SUM(AG27:AG32) -> 1640484.2 | AL33: =SUM(AL27:AL32) -> 0.27534787

Sheet X-Result Summary (Translog)
D2: Tax Rate ($/mi) | E2: Total Revenue | H2: Urban | I2: Rural | J2: Total
C3: Current | D3: ='Translog Model (NEW)'!D1 -> 0.01954489 | E3: =ROUNDUP('Translog Model (NEW)'!N33,-3) -> 1624000 | G3: Old Gini | H3: ='Translog Model (NEW)'!P1 -> 0.72433365 | I3: ='Translog Model (NEW)'!P2 -> 0.72589612 | J3: ='Translog Model (NEW)'!P3 -> 0.72465213
C4: Optimized | D4: ='Translog Model (NEW)'!D2 -> 0.0235 | E4: =ROUNDUP('Translog Model (NEW)'!M33,-3) -> 1646000 | G4: Gini Index | H4: ='Translog Model (NEW)'!N1 -> 0.71862867 | I4: ='Translog Model (NEW)'!N2 -> 0.72217445 | J4: ='Translog Model (NEW)'!N3 -> 0.71907051
C5: %∆ | D5: =(D4-D3)/D3 -> 0.20236031 | E5: =(E4-E3)/E3 -> 0.013546798 | G5: %∆ | H5: =(H4-H3)/H3 -> -0.0078761742 | I5: =(I4-I3)/I3 -> -0.005126999 | J5: =(J4-J3)/J3 -> -0.0077024777
C8: Income Group | D8: HH (#) | E8: Optimized Annual VMT (mi/HH/yr) | F8: Gamma γ | G8: Free Mileage Qh (mi/HH/yr) | I8: Total Taxable VMT | J8: Optimized Revenue R ($) | K8: Current Revenue R ($) | L8: Change in Revenue ∆ ($ ) | M8: Fuel Tax Burden Tˉk ($/HH/yr) | N8: Optimized Gini Index G | O8: Current Gini Index (G)
G9: Qbase (Income Effect) | H9: Extra Mileage ∆g (Area Effect)
B10: Urban | C10: High | D10: ='Translog Model (NEW)'!B7 -> 3001 | E10: ='Translog Model (NEW)'!F7 -> 8230.5912 | F10: ='Translog Model (NEW)'!K7 -> 0 | G10: ='Translog Model (NEW)'!J7 -> 0 | H10: ='X-Old Income Group'!Q7 -> 0 | I10: ='Translog Model (NEW)'!L7 -> 24700004 | J10: ='Translog Model (NEW)'!M7 -> 580450.1 | K10: ='Translog Model (NEW)'!N7 -> 489644.56 | L10: ='Translog Model (NEW)'!O7 -> 90805.538 | M10: ='Translog Model (NEW)'!V7 -> 164.61182 | N10: ='Translog Model (NEW)'!AC7 -> 0.71862867 | O10: ='Translog Model (NEW)'!AM7 -> 0.72433365
C11: Middle High | D11: ='Translog Model (NEW)'!B8 -> 5053 | E11: ='Translog Model (NEW)'!F8 -> 5421.5541 | F11: ='Translog Model (NEW)'!K8 -> 0.1 | G11: ='Translog Model (NEW)'!J8 -> 542.15541 | I11: ='Translog Model (NEW)'!L8 -> 24655602 | J11: ='Translog Model (NEW)'!M8 -> 579406.64 | K11: ='Translog Model (NEW)'!N8 -> 541862.32 | L11: ='Translog Model (NEW)'!O8 -> 37544.317 | M11: ='Translog Model (NEW)'!V8 -> 95.69043
C12: Middle Low | D12: ='Translog Model (NEW)'!B9 -> 3458 | E12: ='Translog Model (NEW)'!F9 -> 3807.8249 | F12: ='Translog Model (NEW)'!K9 -> 0.25 | G12: ='Translog Model (NEW)'!J9 -> 951.95624 | I12: ='Translog Model (NEW)'!L9 -> 9875594 | J12: ='Translog Model (NEW)'!M9 -> 232076.46 | K12: ='Translog Model (NEW)'!N9 -> 259811.17 | L12: ='Translog Model (NEW)'!O9 -> -27734.715 | M12: ='Translog Model (NEW)'!V9 -> 53.785527
C13: Low | D13: ='Translog Model (NEW)'!B10 -> 2090 | E13: ='Translog Model (NEW)'!F10 -> 3868.5466 | F13: ='Translog Model (NEW)'!K10 -> 0.5 | G13: ='Translog Model (NEW)'!J10 -> 1934.2733 | I13: ='Translog Model (NEW)'!L10 -> 4042631.2 | J13: ='Translog Model (NEW)'!M10 -> 95001.833 | K13: ='Translog Model (NEW)'!N10 -> 159035.11 | L13: ='Translog Model (NEW)'!O10 -> -64033.275 | M13: ='Translog Model (NEW)'!V10 -> 31.915509
C14: Total | D14: ='X-Old Income Group'!B13 -> 13602 | E14: ='X-Old Income Group'!F13 -> 21376.821 | G14: ='X-Old Income Group'!J13 -> 2305.4579 | I14: ='X-Old Income Group'!L13 -> 65914101 | J14: ='X-Old Income Group'!M13 -> 1483067.3 | K14: ='X-Old Income Group'!N13 -> 1436565 | L14: ='X-Old Income Group'!O13 -> 46502.288
B15: Rural | C15: High | D15: ='Translog Model (NEW)'!B17 -> 286 | E15: ='Translog Model (NEW)'!F17 -> 9281.62 | F15: ='Translog Model (NEW)'!K17 -> 0 | G15: ='Translog Model (NEW)'!J17 -> 0 | H15: ='X-Old Income Group'!Q17 -> 1000 | I15: ='Translog Model (NEW)'!L17 -> 2368543.3 | J15: ='Translog Model (NEW)'!M17 -> 55660.768 | K15: ='Translog Model (NEW)'!N17 -> 52157.24 | L15: ='Translog Model (NEW)'!O17 -> 3503.5281 | M15: ='Translog Model (NEW)'!V17 -> 162.1324 | N15: ='Translog Model (NEW)'!N2 -> 0.72217445 | O15: ='Translog Model (NEW)'!P2 -> 0.72589612
C16: Middle High | D16: ='Translog Model (NEW)'!B18 -> 551 | E16: ='Translog Model (NEW)'!F18 -> 6802.3383 | F16: ='Translog Model (NEW)'!K18 -> 0.1 | G16: ='Translog Model (NEW)'!J18 -> 680.23383 | I16: ='X-Old Income Group'!L18 -> 2833454.8 | J16: ='X-Old Income Group'!M18 -> 63752.734 | K16: ='X-Old Income Group'!N18 -> 73513.283 | L16: ='X-Old Income Group'!O18 -> -9760.5486 | M16: ='X-Old Income Group'!V18 -> 135.81484
C17: Middle Low | D17: ='Translog Model (NEW)'!B19 -> 409 | E17: ='Translog Model (NEW)'!F19 -> 5642.2646 | F17: ='Translog Model (NEW)'!K19 -> 0.25 | G17: ='Translog Model (NEW)'!J19 -> 1410.5662 | I17: ='X-Old Income Group'!L19 -> 1559042.1 | J17: ='X-Old Income Group'!M19 -> 35078.447 | K17: ='X-Old Income Group'!N19 -> 45170.372 | L17: ='X-Old Income Group'!O19 -> -10091.926 | M17: ='X-Old Income Group'!V19 -> 118.43665
C18: Low | D18: ='Translog Model (NEW)'!B20 -> 273 | E18: ='Translog Model (NEW)'!F20 -> 3612.1155 | F18: ='Translog Model (NEW)'!K20 -> 0.5 | G18: ='Translog Model (NEW)'!J20 -> 1806.0577 | I18: ='X-Old Income Group'!L20 -> 520444.34 | J18: ='X-Old Income Group'!M20 -> 11709.998 | K18: ='X-Old Income Group'!N20 -> 19290.142 | L18: ='X-Old Income Group'!O20 -> -7580.1439 | M18: ='X-Old Income Group'!V20 -> 81.562025
C19: Total | D19: ='X-Old Income Group'!B23 -> 1519 | E19: ='X-Old Income Group'!F23 -> 25431.561 | G19: ='X-Old Income Group'!J23 -> 2723.8685 | I19: ='X-Old Income Group'!L23 -> 7157205.6 | J19: ='X-Old Income Group'!M23 -> 161037.13 | K19: ='X-Old Income Group'!N23 -> 190193.1 | L19: ='X-Old Income Group'!O23 -> -29155.969
B20: Total | C20: High | D20: ='Translog Model (NEW)'!B27 -> 3287 | E20: ='Translog Model (NEW)'!F27 -> 8322.0406 | F20: ='Translog Model (NEW)'!K27 -> 0 | G20: ='Translog Model (NEW)'!J27 -> 0 | H20: - | I20: ='Translog Model (NEW)'!L27 -> 27068547 | J20: ='Translog Model (NEW)'!M27 -> 636110.86 | K20: ='Translog Model (NEW)'!N27 -> 541801.8 | L20: ='Translog Model (NEW)'!O27 -> 94309.066 | M20: ='X-Old Income Group'!V27 -> 116.0674 | N20: ='Translog Model (NEW)'!N3 -> 0.71907051 | O20: ='Translog Model (NEW)'!P3 -> 0.72465213
C21: Middle High | D21: ='Translog Model (NEW)'!B28 -> 5604 | E21: ='Translog Model (NEW)'!F28 -> 5557.3165 | F21: ='Translog Model (NEW)'!K28 -> 0.1 | G21: ='Translog Model (NEW)'!J28 -> 555.73165 | I21: ='Translog Model (NEW)'!L28 -> 27477881 | J21: ='Translog Model (NEW)'!M28 -> 645730.21 | K21: ='Translog Model (NEW)'!N28 -> 615375.61 | L21: ='Translog Model (NEW)'!O28 -> 30354.605 | M21: ='X-Old Income Group'!V28 -> 86.367925
C22: Middle Low | D22: ='Translog Model (NEW)'!B29 -> 3867 | E22: ='Translog Model (NEW)'!F29 -> 4001.8477 | F22: ='Translog Model (NEW)'!K29 -> 0.25 | G22: ='Translog Model (NEW)'!J29 -> 1000.4619 | I22: ='Translog Model (NEW)'!L29 -> 11197359 | J22: ='Translog Model (NEW)'!M29 -> 263137.93 | K22: ='Translog Model (NEW)'!N29 -> 304981.55 | L22: ='Translog Model (NEW)'!O29 -> -41843.617 | M22: ='X-Old Income Group'!V29 -> 69.723741
C23: Low | D23: ='Translog Model (NEW)'!B30 -> 2363 | E23: ='Translog Model (NEW)'!F30 -> 3838.9208 | F23: ='Translog Model (NEW)'!K30 -> 0.5 | G23: ='Translog Model (NEW)'!J30 -> 1919.4604 | I23: ='Translog Model (NEW)'!L30 -> 4262685 | J23: ='Translog Model (NEW)'!M30 -> 100173.1 | K23: ='Translog Model (NEW)'!N30 -> 178325.25 | L23: ='Translog Model (NEW)'!O30 -> -78152.153 | M23: ='X-Old Income Group'!V30 -> 75.633104
C24: Total | D24: ='X-Old Income Group'!B33 -> 15121 | E24: ='X-Old Income Group'!F33 -> 21772.674 | G24: ='X-Old Income Group'!J23 -> 2723.8685 | I24: ='X-Old Income Group'!L33 -> 74590307 | J24: ='X-Old Income Group'!M33 -> 1678281.9 | K24: ='X-Old Income Group'!N33 -> 1626758.1 | L24: ='X-Old Income Group'!O33 -> 51523.819
C28: Income Group | D28: HH (#) | E28: Optimized Annual VMT (mi/HH/yr) | F28: Gamma γ | G28: Free Mileage Qh (mi/HH/yr) | I28: Total Taxable VMT | J28: Optimized Revenue R ($) | K28: Current Revenue R ($) | L28: Change in Revenue ∆ ($ ) | M28: Fuel Tax Burden Tˉk ($/HH/yr) | N28: Optimized Gini Index G | O28: Current Gini Index (G)
G29: Qbase (Income Effect) | H29: Extra Mileage ∆g (Area Effect)
B30: Urban | C30: High | D30: 3001 | E30: 8230.5912 | F30: 0 | G30: 0 | H30: 0 | I30: 24700004 | J30: 555750.09 | K30: 489644.56 | L30: 66105.534 | M30: 164.61182 | N30: 0.72281587 | O30: 0.72433365
C31: Middle High | D31: 5053 | E31: 5421.5541 | F31: 0.1 | G31: 542.15541 | I31: 24655602 | J31: 554751.04 | K31: 541862.32 | L31: 12888.716 | M31: 96.232586
C32: Middle Low | D32: 3458 | E32: 3807.8249 | F32: 0.2 | G32: 761.56499 | I32: 10533967 | J32: 237014.26 | K32: 259811.17 | L32: -22796.918 | M32: 59.021287
C33: Low | D33: 2090 | E33: 3868.5466 | F33: 0.3 | G33: 1160.564 | I33: 5659683.7 | J33: 127342.88 | K33: 159035.11 | L33: -31692.225 | M33: 51.258242
C34: Total | D34: 13602 | E34: 21376.821 | G34: 2305.4579 | I34: 65914101 | J34: 1483067.3 | K34: 1436565 | L34: 46502.288
B35: Rural | C35: High | D35: 286 | E35: 9281.62 | F35: 0 | G35: 0 | H35: 1000 | I35: 2368543.3 | J35: 53292.225 | K35: 52157.24 | L35: 1134.9848 | M35: 163.1324 | N35: 0.73339533 | O35: 0.72589612
C36: Middle High | D36: 551 | E36: 6802.3383 | F36: 0.1 | G36: 680.23383 | I36: 2833454.8 | J36: 63752.734 | K36: 73513.283 | L36: -9760.5486 | M36: 135.81484
C37: Middle Low | D37: 409 | E37: 5642.2646 | F37: 0.2 | G37: 1128.4529 | I37: 1559042.1 | J37: 35078.447 | K37: 45170.372 | L37: -10091.926 | M37: 118.43665
C38: Low | D38: 273 | E38: 3612.1155 | F38: 0.3 | G38: 1083.6346 | I38: 520444.34 | J38: 11709.998 | K38: 19290.142 | L38: -7580.1439 | M38: 81.562025
C39: Total | D39: 1519 | E39: 25431.561 | G39: 2723.8685 | I39: 7157205.6 | J39: 161037.13 | K39: 190193.1 | L39: -29155.969
B40: Total | C40: High | D40: 3287 | E40: 8322.0406 | F40: 0.05 | G40: 416.10203 | H40: - | I40: 25986820 | J40: 584703.45 | K40: 541801.8 | L40: 42901.653 | M40: 116.0674 | N40: 0.72450766 | O40: 0.72465213
C41: Middle High | D41: 5604 | E41: 5557.3165 | F41: 0.1 | G41: 555.73165 | I41: 28028881 | J41: 630649.83 | K41: 615375.61 | L41: 15274.223 | M41: 86.367925
C42: Middle Low | D42: 3867 | E42: 4001.8477 | F42: 0.15 | G42: 600.27715 | I42: 13153873 | J42: 295962.15 | K42: 304981.55 | L42: -9019.4 | M42: 69.723741
C43: Low | D43: 2363 | E43: 3838.9208 | F43: 0.2 | G43: 767.78417 | I43: 7257095.9 | J43: 163284.66 | K43: 178325.25 | L43: -15040.591 | M43: 75.633104
C44: Total | D44: 15121 | E44: 21772.674 | G44: 2723.8685 | I44: 74590307 | J44: 1678281.9 | K44: 1626758.1 | L44: 51523.819

Sheet X-Result Summary
D2: Tax Rate ($/mi) | E2: Total Revenue | H2: Urban | I2: Rural | J2: Total
C3: Current | D3: ='X-Old Income Group'!D1 -> 0.01954489 | E3: =ROUNDUP('X-Old Income Group'!N33,-3) -> 1627000 | G3: Old Gini | H3: ='X-Old Income Group'!P1 -> 0.72433365 | I3: ='X-Old Income Group'!P2 -> 0.72589612 | J3: ='X-Old Income Group'!P3 -> 0.72465213
C4: Optimized | D4: ='X-Old Income Group'!D2 -> 0.0225 | E4: =ROUNDUP('X-Old Income Group'!M33,-3) -> 1679000 | G4: Gini Index | H4: ='X-Old Income Group'!N1 -> 0.72686644 | I4: ='X-Old Income Group'!N2 -> 0.72617025 | J4: ='X-Old Income Group'!N3 -> 0.7266133
C5: %∆ | D5: =(D4-D3)/D3 -> 0.15119604 | E5: =(E4-E3)/E3 -> 0.031960664 | G5: %∆ | H5: =(H4-H3)/H3 -> 0.0034967133 | I5: =(I4-I3)/I3 -> 0.00037764944 | J5: =(J4-J3)/J3 -> 0.002706362
C8: Income Group | D8: HH (#) | E8: Optimized Annual VMT (mi/HH/yr) | F8: Gamma γ | G8: Free Mileage Qh (mi/HH/yr) | I8: Total Taxable VMT | J8: Optimized Revenue R ($) | K8: Current Revenue R ($) | L8: Change in Revenue ∆ ($ ) | M8: Fuel Tax Burden Tˉk ($/HH/yr) | N8: Optimized Gini Index G | O8: Current Gini Index (G)
G9: Qbase (Income Effect) | H9: Extra Mileage ∆g (Area Effect)
B10: Urban | C10: High | D10: ='X-Old Income Group'!B7 -> 3001 | E10: ='X-Old Income Group'!F7 -> 8238.7419 | F10: ='X-Old Income Group'!K7 -> 0.05 | G10: ='X-Old Income Group'!J7 -> 411.9371 | H10: ='X-Old Income Group'!Q7 -> 0 | I10: ='X-Old Income Group'!L7 -> 23488241 | J10: ='X-Old Income Group'!M7 -> 528485.43 | K10: ='X-Old Income Group'!N7 -> 489644.56 | L10: ='X-Old Income Group'!O7 -> 38840.871 | M10: ='X-Old Income Group'!V7 -> 110.2377 | N10: ='X-Old Income Group'!AC7 -> 0.72686644 | O10: ='X-Old Income Group'!AM7 -> 0.72433365
C11: Middle High | D11: ='X-Old Income Group'!B8 -> 5053 | E11: ='X-Old Income Group'!F8 -> 5431.3065 | F11: ='X-Old Income Group'!K8 -> 0.1 | G11: ='X-Old Income Group'!J8 -> 543.13065 | I11: ='X-Old Income Group'!L8 -> 24699953 | J11: ='X-Old Income Group'!M8 -> 555748.93 | K11: ='X-Old Income Group'!N8 -> 541862.32 | L11: ='X-Old Income Group'!O8 -> 13886.611 | M11: ='X-Old Income Group'!V8 -> 80.976028
C12: Middle Low | D12: ='X-Old Income Group'!B9 -> 3458 | E12: ='X-Old Income Group'!F9 -> 3819.2878 | F12: ='X-Old Income Group'!K9 -> 0.15 | G12: ='X-Old Income Group'!J9 -> 572.89317 | I12: ='X-Old Income Group'!L9 -> 11226033 | J12: ='X-Old Income Group'!M9 -> 252585.74 | K12: ='X-Old Income Group'!N9 -> 259811.17 | L12: ='X-Old Income Group'!O9 -> -7225.4382 | M12: ='X-Old Income Group'!V9 -> 63.962151
C13: Low | D13: ='X-Old Income Group'!B10 -> 2090 | E13: ='X-Old Income Group'!F10 -> 3887.4848 | F13: ='X-Old Income Group'!K10 -> 0.2 | G13: ='X-Old Income Group'!J10 -> 777.49696 | I13: ='X-Old Income Group'!L10 -> 6499874.6 | J13: ='X-Old Income Group'!M10 -> 146247.18 | K13: ='X-Old Income Group'!N10 -> 159035.11 | L13: ='X-Old Income Group'!O10 -> -12787.929 | M13: ='X-Old Income Group'!V10 -> 74.858656
C14: Total | D14: ='X-Old Income Group'!B13 -> 13602 | E14: ='X-Old Income Group'!F13 -> 21376.821 | G14: ='X-Old Income Group'!J13 -> 2305.4579 | I14: ='X-Old Income Group'!L13 -> 65914101 | J14: ='X-Old Income Group'!M13 -> 1483067.3 | K14: ='X-Old Income Group'!N13 -> 1436565 | L14: ='X-Old Income Group'!O13 -> 46502.288
B15: Rural | C15: High | D15: ='X-Old Income Group'!B17 -> 286 | E15: ='X-Old Income Group'!F17 -> 9312.7138 | F15: ='X-Old Income Group'!K17 -> 0.05 | G15: ='X-Old Income Group'!J17 -> 465.63569 | H15: ='X-Old Income Group'!Q17 -> 1000 | I15: ='X-Old Income Group'!L17 -> 2244264.3 | J15: ='X-Old Income Group'!M17 -> 50495.948 | K15: ='X-Old Income Group'!N17 -> 52157.24 | L15: ='X-Old Income Group'!O17 -> -1661.292 | M15: ='X-Old Income Group'!V17 -> 177.2385 | N15: ='X-Old Income Group'!N2 -> 0.72617025 | O15: ='X-Old Income Group'!P2 -> 0.72589612
C16: Middle High | D16: ='X-Old Income Group'!B18 -> 551 | E16: ='X-Old Income Group'!F18 -> 6824.8737 | F16: ='X-Old Income Group'!K18 -> 0.1 | G16: ='X-Old Income Group'!J18 -> 682.48737 | I16: ='X-Old Income Group'!L18 -> 2833454.8 | J16: ='X-Old Income Group'!M18 -> 63752.734 | K16: ='X-Old Income Group'!N18 -> 73513.283 | L16: ='X-Old Income Group'!O18 -> -9760.5486 | M16: ='X-Old Income Group'!V18 -> 135.81484
C17: Middle Low | D17: ='X-Old Income Group'!B19 -> 409 | E17: ='X-Old Income Group'!F19 -> 5660.9869 | F17: ='X-Old Income Group'!K19 -> 0.15 | G17: ='X-Old Income Group'!J19 -> 849.14803 | I17: ='X-Old Income Group'!L19 -> 1559042.1 | J17: ='X-Old Income Group'!M19 -> 35078.447 | K17: ='X-Old Income Group'!N19 -> 45170.372 | L17: ='X-Old Income Group'!O19 -> -10091.926 | M17: ='X-Old Income Group'!V19 -> 118.43665
C18: Low | D18: ='X-Old Income Group'!B20 -> 273 | E18: ='X-Old Income Group'!F20 -> 3632.9869 | F18: ='X-Old Income Group'!K20 -> 0.2 | G18: ='X-Old Income Group'!J20 -> 726.59738 | I18: ='X-Old Income Group'!L20 -> 520444.34 | J18: ='X-Old Income Group'!M20 -> 11709.998 | K18: ='X-Old Income Group'!N20 -> 19290.142 | L18: ='X-Old Income Group'!O20 -> -7580.1439 | M18: ='X-Old Income Group'!V20 -> 81.562025
C19: Total | D19: ='X-Old Income Group'!B23 -> 1519 | E19: ='X-Old Income Group'!F23 -> 25431.561 | G19: ='X-Old Income Group'!J23 -> 2723.8685 | I19: ='X-Old Income Group'!L23 -> 7157205.6 | J19: ='X-Old Income Group'!M23 -> 161037.13 | K19: ='X-Old Income Group'!N23 -> 190193.1 | L19: ='X-Old Income Group'!O23 -> -29155.969
B20: Total | C20: High | D20: ='X-Old Income Group'!B27 -> 3287 | E20: ='X-Old Income Group'!F27 -> 8332.1876 | F20: ='X-Old Income Group'!K27 -> 0.05 | G20: ='X-Old Income Group'!J27 -> 416.60938 | H20: - | I20: ='X-Old Income Group'!L27 -> 26018506 | J20: ='X-Old Income Group'!M27 -> 585416.38 | K20: ='X-Old Income Group'!N27 -> 541801.8 | L20: ='X-Old Income Group'!O27 -> 43614.579 | M20: ='X-Old Income Group'!V27 -> 116.0674 | N20: ='X-Old Income Group'!N3 -> 0.7266133 | O20: ='X-Old Income Group'!P3 -> 0.72465213
C21: Middle High | D21: ='X-Old Income Group'!B28 -> 5604 | E21: ='X-Old Income Group'!F28 -> 5568.3257 | F21: ='X-Old Income Group'!K28 -> 0.1 | G21: ='X-Old Income Group'!J28 -> 556.83257 | I21: ='X-Old Income Group'!L28 -> 28084407 | J21: ='X-Old Income Group'!M28 -> 631899.17 | K21: ='X-Old Income Group'!N28 -> 615375.61 | L21: ='X-Old Income Group'!O28 -> 16523.562 | M21: ='X-Old Income Group'!V28 -> 86.367925
C22: Middle Low | D22: ='X-Old Income Group'!B29 -> 3867 | E22: ='X-Old Income Group'!F29 -> 4014.0783 | F22: ='X-Old Income Group'!K29 -> 0.15 | G22: ='X-Old Income Group'!J29 -> 602.11175 | I22: ='X-Old Income Group'!L29 -> 13194075 | J22: ='X-Old Income Group'!M29 -> 296866.68 | K22: ='X-Old Income Group'!N29 -> 304981.55 | L22: ='X-Old Income Group'!O29 -> -8114.8637 | M22: ='X-Old Income Group'!V29 -> 69.723741
C23: Low | D23: ='X-Old Income Group'!B30 -> 2363 | E23: ='X-Old Income Group'!F30 -> 3858.0824 | F23: ='X-Old Income Group'!K30 -> 0.2 | G23: ='X-Old Income Group'!J30 -> 771.61648 | I23: ='X-Old Income Group'!L30 -> 7293318.9 | J23: ='X-Old Income Group'!M30 -> 164099.68 | K23: ='X-Old Income Group'!N30 -> 178325.25 | L23: ='X-Old Income Group'!O30 -> -14225.573 | M23: ='X-Old Income Group'!V30 -> 75.633104
C24: Total | D24: ='X-Old Income Group'!B33 -> 15121 | E24: ='X-Old Income Group'!F33 -> 21772.674 | G24: ='X-Old Income Group'!J23 -> 2723.8685 | I24: ='X-Old Income Group'!L33 -> 74590307 | J24: ='X-Old Income Group'!M33 -> 1678281.9 | K24: ='X-Old Income Group'!N33 -> 1626758.1 | L24: ='X-Old Income Group'!O33 -> 51523.819

Sheet X-Old Income Group
A1: **current tax rate/mile r ($/mi) = | D1: 0.01954489 | F1: Current Total Revenue R ($) | H1: =N13+N23 -> 1626758.1 | L1: Urban Gini Index (G) = | N1: =AC7 -> 0.72686644 | O1: Old Gini Index (No free mileage) | P1: =AM7 -> 0.72433365 | Q1: =N1/P1-1 -> 0.0034967133
A2: **optimized tax rate/mile r ($/mi) = | D2: 0.0225 | F2: Optimized Total Revenue R ($) | H2: =M13+M23 -> 1644104.4 | L2: Rural Gini Index (G) = | N2: =AC17 -> 0.72617025 | P2: =AM17 -> 0.72589612 | Q2: =N2/P2-1 -> 0.00037764944
F3: ∆ ($ ) | G3: + | H3: =O13+O23 -> 17346.319 | I3: =H2/H1-1 -> 0.010663121 | L3: Total Gini Index (G) = | N3: =AC27 -> 0.7266133 | P3: =AM27 -> 0.72465213 | Q3: =N3/P3-1 -> 0.002706362 | S3: Free Mileage Quota Q (mi/HH/yr) | V3: Gini Index with Free Mileage Quota | AF3: Old Gini Index without Mileage Quota
J4: Auto Updated | K4: Adjusted parameter | S4: Adjusted Q | T4: Auto Updated
A5: Urban | J5: TBD | K5: TBD | Q5: TBD | V5: TBD | AF5: TBD | AS5: NEW | AV5: OLD
A6: Income Group | B6: HH (#) | C6: Current Weekly VMT (mi/wk) | D6: Current Annual VMT (mi/HH/yr) | E6: Predicted Weekly VMT (mi/HH/wk) | F6: Predicted VMT (mi/HH/yr) | H6: Current VMT (mi/HH/yr) | I6: Predicted VMT (mi/HH/yr) | J6: Free Mileage Quota Q (mi/HH/yr) | K6: beta ß | L6: VMT (taxable) | M6: Optimized Revenue R ($) | N6: Current Revenue R ($) | O6: ∆ ($ ) | Q6: Extra Mileage ∆g | S6: Q after ß | T6: beta ß | V6: Fuel Tax Burden Tˉk ($/HH/yr) | W6: Nk​*Tˉk | X6: Tax Share Sk | Y6: Cum Tax Share Lk | Z6: HH Share wk | AA6: Cum HH Share Pk | AC6: Gini Index | AF6: Fuel Tax Burden Tˉk ($/HH/yr) | AG6: Nk​*Tˉk | AH6: Tax Share Sk | AI6: Cum Tax Share Lk | AJ6: HH Share wk | AK6: Cum HH Share Pk | AM6: Gini Index | AR6: Urban | AS6: Cum Tax Share Lk | AT6: Cum HH Share Pk | AV6: Cum Tax Share Lk | AW6: Cum HH Share Pk
A7: H | B7: 3001 | C7: 160.53819 | D7: =C7*52 -> 8347.9859 | E7: 158.43734 | F7: =52*E7 -> 8238.7419 | H7: =C7*52*B7 -> 25052306 | I7: =F7*B7 -> 24724464 | J7: =K7*F7 -> 411.9371 | K7: 0.05 | L7: =B7*(F7-J7-Q7) -> 23488241 | M7: =L7*$D$2 -> 528485.43 | N7: =H7*$D$1 -> 489644.56 | O7: =M7-N7 -> 38840.871 | Q7: 0 | S7: 0 | T7: =S7/F7 -> 0 | V7: 110.2377 | W7: =B7*V7 -> 330823.34 | X7: =W7/$W$13 -> 0.2960041 | Y7: =X7 -> 0.2960041 | Z7: =B7/$B$13 -> 0.22062932 | AA7: =Z7 -> 0.22062932 | AB7: =Y7*AA7 -> 0.065307184 | AC7: =1-AB13 -> 0.72686644 | AD7: =Y7*AA7 -> 0.065307184 | AF7: =N7/B7 -> 163.16047 | AG7: =B7*AF7 -> 489644.56 | AH7: =AG7/$AG$13 -> 0.33760368 | AI7: =AH7 -> 0.33760368 | AJ7: =B7/$B$13 -> 0.22062932 | AK7: =AJ7 -> 0.22062932 | AL7: =AI7*AK7 -> 0.074485269 | AM7: =1-AL13 -> 0.72433365 | AN7: =AI7*AK7 -> 0.074485269 | AS7: =Y7 -> 0.2960041 | AT7: =AA7 -> 0.22062932 | AV7: =AI7 -> 0.33760368 | AW7: =AK7 -> 0.22062932
A8: MH | B8: 5053 | C8: 105.5123 | D8: =C8*52 -> 5486.6395 | E8: 104.4482 | F8: =52*E8 -> 5431.3065 | H8: =C8*52*B8 -> 27723989 | I8: =F8*B8 -> 27444392 | J8: =K8*F8 -> 543.13065 | K8: 0.1 | L8: =B8*(F8-J8-Q8) -> 24699953 | M8: =L8*$D$2 -> 555748.93 | N8: =H8*$D$1 -> 541862.32 | O8: =M8-N8 -> 13886.611 | Q8: 0 | S8: 500 | T8: =S8/F8 -> 0.092058881 | V8: 80.976028 | W8: =B8*V8 -> 409171.87 | X8: =W8/$W$13 -> 0.36610644 | Y8: =X8+Y7 -> 0.66211054 | Z8: =B8/$B$13 -> 0.37148949 | AA8: =Z8+AA7 -> 0.59211881 | AB8: =(Y8-Y7)*(AA8-AA7) -> 0.13600469 | AD8: =Y8*AA8 -> 0.3920481 | AF8: =N8/B8 -> 107.23577 | AG8: =B8*AF8 -> 541862.32 | AH8: =AG8/$AG$13 -> 0.37360716 | AI8: =AH8+AI7 -> 0.71121083 | AJ8: =B8/$B$13 -> 0.37148949 | AK8: =AJ8+AK7 -> 0.59211881 | AL8: =(AI8-AI7)*(AK8-AK7) -> 0.13879113 | AN8: =AI8*AK8 -> 0.42112131 | AS8: =Y8 -> 0.66211054 | AT8: =AA8 -> 0.59211881 | AV8: =AI8 -> 0.71121083 | AW8: =AK8 -> 0.59211881
A9: ML | B9: 3458 | C9: 73.925839 | D9: =C9*52 -> 3844.1436 | E9: 73.447843 | F9: =52*E9 -> 3819.2878 | H9: =C9*52*B9 -> 13293049 | I9: =F9*B9 -> 13207097 | J9: =K9*F9 -> 572.89317 | K9: 0.15 | L9: =B9*(F9-J9-Q9) -> 11226033 | M9: =L9*$D$2 -> 252585.74 | N9: =H9*$D$1 -> 259811.17 | O9: =M9-N9 -> -7225.4382 | Q9: 0 | S9: 1000 | T9: =S9/F9 -> 0.26182892 | V9: 63.962151 | W9: =B9*V9 -> 221181.12 | X9: =W9/$W$13 -> 0.19790175 | Y9: =X9+Y8 -> 0.86001229 | Z9: =B9/$B$13 -> 0.25422732 | AA9: =Z9+AA8 -> 0.84634613 | AB9: =(Y9-Y8)*(AA9-AA8) -> 0.050312032 | AD9: =Y9*AA9 -> 0.72786807 | AF9: =N9/B9 -> 75.133364 | AG9: =B9*AF9 -> 259811.17 | AH9: =AG9/$AG$13 -> 0.17913649 | AI9: =AH9+AI8 -> 0.89034732 | AJ9: =B9/$B$13 -> 0.25422732 | AK9: =AJ9+AK8 -> 0.84634613 | AL9: =(AI9-AI8)*(AK9-AK8) -> 0.04554139 | AN9: =AI9*AK9 -> 0.75354201 | AS9: =Y9 -> 0.86001229 | AT9: =AA9 -> 0.84634613 | AV9: =AI9 -> 0.89034732 | AW9: =AK9 -> 0.84634613
A10: L | B10: 2090 | C10: 74.870399 | D10: =C10*52 -> 3893.2607 | E10: 74.759323 | F10: =52*E10 -> 3887.4848 | H10: =C10*52*B10 -> 8136915 | I10: =F10*B10 -> 8124843.3 | J10: =K10*F10 -> 777.49696 | K10: 0.2 | L10: =B10*(F10-J10-Q10) -> 6499874.6 | M10: =L10*$D$2 -> 146247.18 | N10: =H10*$D$1 -> 159035.11 | O10: =M10-N10 -> -12787.929 | Q10: 0 | S10: 2000 | T10: =S10/F10 -> 0.51447146 | V10: 74.858656 | W10: =B10*V10 -> 156454.59 | X10: =W10/$W$13 -> 0.13998771 | Y10: =X10+Y9 -> 1 | Z10: =B10/$B$13 -> 0.15365387 | AA10: =Z10+AA9 -> 1 | AB10: =(Y10-Y9)*(AA10-AA9) -> 0.021509654 | AD10: =Y10*AA10 -> 1 | AF10: =N10/B10 -> 76.093353 | AG10: =B10*AF10 -> 159035.11 | AH10: =AG10/$AG$13 -> 0.10965268 | AI10: =AH10+AI9 -> 1 | AJ10: =B10/$B$13 -> 0.15365387 | AK10: =AJ10+AK9 -> 1 | AL10: =(AI10-AI9)*(AK10-AK9) -> 0.016848559 | AN10: =AI10*AK10 -> 1 | AS10: =Y10 -> 1 | AT10: =AA10 -> 1 | AV10: =AI10 -> 1 | AW10: =AK10 -> 1
A13: Ntotal | B13: =SUM(B7:B12) -> 13602 | E13: =SUM(E7:E10)/4 -> 102.77318 | F13: =SUM(F7:F12) -> 21376.821 | H13: =SUM(H7:H12) -> 74206259 | I13: =SUM(I7:I12) -> 73500797 | J13: =SUM(J7:J12) -> 2305.4579 | L13: =SUM(L7:L12) -> 65914101 | M13: =L13*$D$2 -> 1483067.3 | N13: =I13*$D$1 -> 1436565 | O13: =M13-N13 -> 46502.288 | Q13: =SUM(Q7:Q12) -> 0 | S13: =SUM(S7:S12) -> 3500 | W13: =SUM(W7:W12) -> 1117630.9 | AB13: =SUM(AB7:AB12) -> 0.27313356 | AG13: =SUM(AG7:AG12) -> 1450353.2 | AL13: =SUM(AL7:AL12) -> 0.27566635
A15: Rural | AS15: NEW | AV15: OLD
A16: Income Group | B16: HH (#) | C16: Current Mean VMT (mi/d) | D16: Current Annual (mi/HH/yr) | E16: Predicted Weekly VMT (mi/HH/wk) | F16: Predicted VMT (mi/HH/yr) | H16: Current VMT (mi/HH/yr) | I16: VMT (mi/HH/yr) | J16: Free Mileage Quota Q (mi/HH/yr) | K16: beta ß | L16: VMT (taxable) | M16: Optimized Revenue R ($) | N16: Current Revenue R ($) | O16: ∆ ($ ) | Q16: ∆g | S16: Q after ß | T16: beta ß | V16: Fuel Tax Burden Tˉk ($/HH/yr) | W16: Nk​*Tˉk | X16: Tax Share Sk | Y16: Cum Tax Share Lk | Z16: HH Share wk | AA16: Cum HH Share Pk | AC16: Gini Index | AF16: Fuel Tax Burden Tˉk ($/HH/yr) | AG16: Nk​*Tˉk | AH16: Tax Share Sk | AI16: Cum Tax Share Lk | AJ16: HH Share wk | AK16: Cum HH Share Pk | AM16: Gini Index | AR16: Rural | AS16: Cum Tax Share Lk | AT16: Cum HH Share Pk | AV16: Cum Tax Share Lk | AW16: Cum HH Share Pk
A17: H | B17: 286 | C17: 179.437 | D17: =C17*52 -> 9330.7238 | E17: 179.09065 | F17: =52*E17 -> 9312.7138 | H17: =C17*52*B17 -> 2668587 | I17: =F17*B17 -> 2663436.1 | J17: =K17*F17 -> 465.63569 | K17: 0.05 | L17: =B17*(F17-J17-Q17) -> 2244264.3 | M17: =L17*$D$2 -> 50495.948 | N17: =H17*$D$1 -> 52157.24 | O17: =M17-N17 -> -1661.292 | Q17: 1000 | S17: 0 | T17: =S17/F17 -> 0 | V17: 177.2385 | W17: =B17*V17 -> 50690.21 | X17: =W17/$W$23 -> 0.25831879 | Y17: =X17 -> 0.25831879 | Z17: =B17/$B$23 -> 0.18828176 | AA17: =Z17 -> 0.18828176 | AB17: =Y17*AA17 -> 0.048636718 | AC17: =1-AB23 -> 0.72617025 | AD17: =Y17*AA17 -> 0.048636718 | AF17: =N17/B17 -> 182.36797 | AG17: =B17*AF17 -> 52157.24 | AH17: =AG17/$AG$23 -> 0.2743226 | AI17: =AH17 -> 0.2743226 | AJ17: =B17/$B$23 -> 0.18828176 | AK17: =AJ17 -> 0.18828176 | AL17: =AI17*AK17 -> 0.051649943 | AM17: =1-AL23 -> 0.72589612 | AN17: =AI17*AK17 -> 0.051649943 | AS17: =Y17 -> 0.25831879 | AT17: =AA17 -> 0.18828176 | AV17: =AI17 -> 0.2743226 | AW17: =AK17 -> 0.18828176
A18: MH | B18: 551 | C18: 131.27367 | D18: =C18*52 -> 6826.2311 | E18: 131.24757 | F18: =52*E18 -> 6824.8737 | H18: =C18*52*B18 -> 3761253.3 | I18: =F18*B18 -> 3760505.4 | J18: =K18*F18 -> 682.48737 | K18: 0.1 | L18: =B18*(F18-J18-Q18) -> 2833454.8 | M18: =L18*$D$2 -> 63752.734 | N18: =H18*$D$1 -> 73513.283 | O18: =M18-N18 -> -9760.5486 | Q18: 1000 | S18: 1000 | T18: =S18/F18 -> 0.14652286 | V18: 135.81484 | W18: =B18*V18 -> 74833.978 | X18: =W18/$W$23 -> 0.38135615 | Y18: =X18+Y17 -> 0.63967494 | Z18: =B18/$B$23 -> 0.36273864 | AA18: =Z18+AA17 -> 0.55102041 | AB18: =(Y18-Y17)*(AA18-AA17) -> 0.13833261 | AD18: =Y18*AA18 -> 0.35247395 | AF18: =N18/B18 -> 133.41794 | AG18: =B18*AF18 -> 73513.283 | AH18: =AG18/$AG$23 -> 0.38664536 | AI18: =AH18+AI17 -> 0.66096796 | AJ18: =B18/$B$23 -> 0.36273864 | AK18: =AJ18+AK17 -> 0.55102041 | AL18: =(AI18-AI17)*(AK18-AK17) -> 0.14025121 | AN18: =AI18*AK18 -> 0.36420683 | AS18: =Y18 -> 0.63967494 | AT18: =AA18 -> 0.55102041 | AV18: =AI18 -> 0.66096796 | AW18: =AK18 -> 0.55102041
A19: ML | B19: 409 | C19: 108.66603 | D19: =C19*52 -> 5650.6334 | E19: 108.86513 | F19: =52*E19 -> 5660.9869 | H19: =C19*52*B19 -> 2311109.1 | I19: =F19*B19 -> 2315343.6 | J19: =K19*F19 -> 849.14803 | K19: 0.15 | L19: =B19*(F19-J19-Q19) -> 1559042.1 | M19: =L19*$D$2 -> 35078.447 | N19: =H19*$D$1 -> 45170.372 | O19: =M19-N19 -> -10091.926 | Q19: 1000 | S19: 2000 | T19: =S19/F19 -> 0.35329529 | V19: 118.43665 | W19: =B19*V19 -> 48440.589 | X19: =W19/$W$23 -> 0.24685466 | Y19: =X19+Y18 -> 0.8865296 | Z19: =B19/$B$23 -> 0.26925609 | AA19: =Z19+AA18 -> 0.8202765 | AB19: =(Y19-Y18)*(AA19-AA18) -> 0.066467121 | AD19: =Y19*AA19 -> 0.7271994 | AF19: =N19/B19 -> 110.44101 | AG19: =B19*AF19 -> 45170.372 | AH19: =AG19/$AG$23 -> 0.23757495 | AI19: =AH19+AI18 -> 0.89854291 | AJ19: =B19/$B$23 -> 0.26925609 | AK19: =AJ19+AK18 -> 0.8202765 | AL19: =(AI19-AI18)*(AK19-AK18) -> 0.063968503 | AN19: =AI19*AK19 -> 0.73705363 | AS19: =Y19 -> 0.8865296 | AT19: =AA19 -> 0.8202765 | AV19: =AI19 -> 0.89854291 | AW19: =AK19 -> 0.8202765
